__rethrow_casa_exceptions = True
h_init()
try:
    hifa_restoredata (vis=['uid___A002_Xcccc19_Xb7a6', 'uid___A002_Xccde5b_X5258', 'uid___A002_Xccde5b_X5ef0', 'uid___A002_Xccea8d_X3fee', 'uid___A002_Xccea8d_Xeed1', 'uid___A002_Xcd07af_X5991', 'uid___A002_Xcd1950_X40d9', 'uid___A002_Xcd1950_X6006', 'uid___A002_Xcd2acd_X5fab', 'uid___A002_Xcd3dcc_X21cd'], session=['session_2', 'session_3', 'session_4', 'session_5', 'session_6', 'session_7', 'session_8', 'session_9', 'session_10', 'session_11'], ocorr_mode='ca')
finally:
    h_save()
